Traceback (most recent call last):
  File "/Users/ujwal/Desktop/sakana_ai_sol/nanoGPTUjwal/train.py", line 265, in <module>
    losses = estimate_loss()
  File "/Users/ujwal/.pyenv/versions/3.10.0/lib/python3.10/site-packages/torch/utils/_contextlib.py", line 115, in decorate_context
    return func(*args, **kwargs)
  File "/Users/ujwal/Desktop/sakana_ai_sol/nanoGPTUjwal/train.py", line 225, in estimate_loss
    logits, loss = model(X, Y)
  File "/Users/ujwal/.pyenv/versions/3.10.0/lib/python3.10/site-packages/torch/nn/modules/module.py", line 1532, in _wrapped_call_impl
    return self._call_impl(*args, **kwargs)
  File "/Users/ujwal/.pyenv/versions/3.10.0/lib/python3.10/site-packages/torch/nn/modules/module.py", line 1541, in _call_impl
    return forward_call(*args, **kwargs)
  File "/Users/ujwal/Desktop/sakana_ai_sol/nanoGPTUjwal/model.py", line 234, in forward
    logits = self.lm_head(x)
  File "/Users/ujwal/.pyenv/versions/3.10.0/lib/python3.10/site-packages/torch/nn/modules/module.py", line 1532, in _wrapped_call_impl
    return self._call_impl(*args, **kwargs)
  File "/Users/ujwal/.pyenv/versions/3.10.0/lib/python3.10/site-packages/torch/nn/modules/module.py", line 1541, in _call_impl
    return forward_call(*args, **kwargs)
  File "/Users/ujwal/.pyenv/versions/3.10.0/lib/python3.10/site-packages/torch/nn/modules/linear.py", line 116, in forward
    return F.linear(input, self.weight, self.bias)
RuntimeError: Invalid buffer size: 12.28 GB
